2025-10-09 10:38:25,192 | INFO | Fetching all students from database...
2025-10-09 10:38:25,193 | INFO | GET /students | Status: 200 | Duration: 0.003s
2025-10-09 10:38:35,023 | ERROR | Exception in GET /error-demo: Simulated error for testing logs
Traceback (most recent call last):
  File "C:\Users\user1\AppData\Local\Programs\Python\Python311\Lib\site-packages\anyio\streams\memory.py", line 98, in receive
    return self.receive_nowait()
           ^^^^^^^^^^^^^^^^^^^^^
  File "C:\Users\user1\AppData\Local\Programs\Python\Python311\Lib\site-packages\anyio\streams\memory.py", line 93, in receive_nowait
    raise WouldBlock
anyio.WouldBlock

During handling of the above exception, another exception occurred:

Traceback (most recent call last):
  File "C:\Users\user1\AppData\Local\Programs\Python\Python311\Lib\site-packages\starlette\middleware\base.py", line 151, in call_next
    message = await recv_stream.receive()
              ^^^^^^^^^^^^^^^^^^^^^^^^^^^
  File "C:\Users\user1\AppData\Local\Programs\Python\Python311\Lib\site-packages\anyio\streams\memory.py", line 118, in receive
    raise EndOfStream
anyio.EndOfStream

During handling of the above exception, another exception occurred:

Traceback (most recent call last):
  File "C:\Users\user1\Desktop\fastapi\logtest.py", line 21, in log_requests
    response = await call_next(request)
               ^^^^^^^^^^^^^^^^^^^^^^^^
  File "C:\Users\user1\AppData\Local\Programs\Python\Python311\Lib\site-packages\starlette\middleware\base.py", line 159, in call_next
    raise app_exc
  File "C:\Users\user1\AppData\Local\Programs\Python\Python311\Lib\site-packages\starlette\middleware\base.py", line 144, in coro
    await self.app(scope, receive_or_disconnect, send_no_error)
  File "C:\Users\user1\AppData\Local\Programs\Python\Python311\Lib\site-packages\starlette\middleware\exceptions.py", line 63, in __call__
    await wrap_app_handling_exceptions(self.app, conn)(scope, receive, send)
  File "C:\Users\user1\AppData\Local\Programs\Python\Python311\Lib\site-packages\starlette\_exception_handler.py", line 53, in wrapped_app
    raise exc
  File "C:\Users\user1\AppData\Local\Programs\Python\Python311\Lib\site-packages\starlette\_exception_handler.py", line 42, in wrapped_app
    await app(scope, receive, sender)
  File "C:\Users\user1\AppData\Local\Programs\Python\Python311\Lib\site-packages\starlette\routing.py", line 716, in __call__
    await self.middleware_stack(scope, receive, send)
  File "C:\Users\user1\AppData\Local\Programs\Python\Python311\Lib\site-packages\starlette\routing.py", line 736, in app
    await route.handle(scope, receive, send)
  File "C:\Users\user1\AppData\Local\Programs\Python\Python311\Lib\site-packages\starlette\routing.py", line 290, in handle
    await self.app(scope, receive, send)
  File "C:\Users\user1\AppData\Local\Programs\Python\Python311\Lib\site-packages\starlette\routing.py", line 78, in app
    await wrap_app_handling_exceptions(app, request)(scope, receive, send)
  File "C:\Users\user1\AppData\Local\Programs\Python\Python311\Lib\site-packages\starlette\_exception_handler.py", line 53, in wrapped_app
    raise exc
  File "C:\Users\user1\AppData\Local\Programs\Python\Python311\Lib\site-packages\starlette\_exception_handler.py", line 42, in wrapped_app
    await app(scope, receive, sender)
  File "C:\Users\user1\AppData\Local\Programs\Python\Python311\Lib\site-packages\starlette\routing.py", line 75, in app
    response = await f(request)
               ^^^^^^^^^^^^^^^^
  File "C:\Users\user1\AppData\Local\Programs\Python\Python311\Lib\site-packages\fastapi\routing.py", line 308, in app
    raw_response = await run_endpoint_function(
                   ^^^^^^^^^^^^^^^^^^^^^^^^^^^^
  File "C:\Users\user1\AppData\Local\Programs\Python\Python311\Lib\site-packages\fastapi\routing.py", line 221, in run_endpoint_function
    return await run_in_threadpool(dependant.call, **values)
           ^^^^^^^^^^^^^^^^^^^^^^^^^^^^^^^^^^^^^^^^^^^^^^^^^
  File "C:\Users\user1\AppData\Local\Programs\Python\Python311\Lib\site-packages\starlette\concurrency.py", line 38, in run_in_threadpool
    return await anyio.to_thread.run_sync(func)
           ^^^^^^^^^^^^^^^^^^^^^^^^^^^^^^^^^^^^
  File "C:\Users\user1\AppData\Local\Programs\Python\Python311\Lib\site-packages\anyio\to_thread.py", line 33, in run_sync
    return await get_asynclib().run_sync_in_worker_thread(
           ^^^^^^^^^^^^^^^^^^^^^^^^^^^^^^^^^^^^^^^^^^^^^^^
  File "C:\Users\user1\AppData\Local\Programs\Python\Python311\Lib\site-packages\anyio\_backends\_asyncio.py", line 877, in run_sync_in_worker_thread
    return await future
           ^^^^^^^^^^^^
  File "C:\Users\user1\AppData\Local\Programs\Python\Python311\Lib\site-packages\anyio\_backends\_asyncio.py", line 807, in run
    result = context.run(func, *args)
             ^^^^^^^^^^^^^^^^^^^^^^^^
  File "C:\Users\user1\Desktop\fastapi\logtest.py", line 44, in error_demo
    raise ValueError("Simulated error for testing logs")
ValueError: Simulated error for testing logs

2025-10-09 10:38:35,070 | ERROR | Unhandled error in /error-demo: Simulated error for testing logs
Traceback (most recent call last):
  File "C:\Users\user1\AppData\Local\Programs\Python\Python311\Lib\site-packages\anyio\streams\memory.py", line 98, in receive
    return self.receive_nowait()
           ^^^^^^^^^^^^^^^^^^^^^
  File "C:\Users\user1\AppData\Local\Programs\Python\Python311\Lib\site-packages\anyio\streams\memory.py", line 93, in receive_nowait
    raise WouldBlock
anyio.WouldBlock

During handling of the above exception, another exception occurred:

Traceback (most recent call last):
  File "C:\Users\user1\AppData\Local\Programs\Python\Python311\Lib\site-packages\starlette\middleware\base.py", line 151, in call_next
    message = await recv_stream.receive()
              ^^^^^^^^^^^^^^^^^^^^^^^^^^^
  File "C:\Users\user1\AppData\Local\Programs\Python\Python311\Lib\site-packages\anyio\streams\memory.py", line 118, in receive
    raise EndOfStream
anyio.EndOfStream

During handling of the above exception, another exception occurred:

Traceback (most recent call last):
  File "C:\Users\user1\AppData\Local\Programs\Python\Python311\Lib\site-packages\starlette\middleware\errors.py", line 164, in __call__
    await self.app(scope, receive, _send)
  File "C:\Users\user1\AppData\Local\Programs\Python\Python311\Lib\site-packages\starlette\middleware\base.py", line 184, in __call__
    response = await self.dispatch_func(request, call_next)
               ^^^^^^^^^^^^^^^^^^^^^^^^^^^^^^^^^^^^^^^^^^^^
  File "C:\Users\user1\Desktop\fastapi\logtest.py", line 27, in log_requests
    raise e
  File "C:\Users\user1\Desktop\fastapi\logtest.py", line 21, in log_requests
    response = await call_next(request)
               ^^^^^^^^^^^^^^^^^^^^^^^^
  File "C:\Users\user1\AppData\Local\Programs\Python\Python311\Lib\site-packages\starlette\middleware\base.py", line 159, in call_next
    raise app_exc
  File "C:\Users\user1\AppData\Local\Programs\Python\Python311\Lib\site-packages\starlette\middleware\base.py", line 144, in coro
    await self.app(scope, receive_or_disconnect, send_no_error)
  File "C:\Users\user1\AppData\Local\Programs\Python\Python311\Lib\site-packages\starlette\middleware\exceptions.py", line 63, in __call__
    await wrap_app_handling_exceptions(self.app, conn)(scope, receive, send)
  File "C:\Users\user1\AppData\Local\Programs\Python\Python311\Lib\site-packages\starlette\_exception_handler.py", line 53, in wrapped_app
    raise exc
  File "C:\Users\user1\AppData\Local\Programs\Python\Python311\Lib\site-packages\starlette\_exception_handler.py", line 42, in wrapped_app
    await app(scope, receive, sender)
  File "C:\Users\user1\AppData\Local\Programs\Python\Python311\Lib\site-packages\starlette\routing.py", line 716, in __call__
    await self.middleware_stack(scope, receive, send)
  File "C:\Users\user1\AppData\Local\Programs\Python\Python311\Lib\site-packages\starlette\routing.py", line 736, in app
    await route.handle(scope, receive, send)
  File "C:\Users\user1\AppData\Local\Programs\Python\Python311\Lib\site-packages\starlette\routing.py", line 290, in handle
    await self.app(scope, receive, send)
  File "C:\Users\user1\AppData\Local\Programs\Python\Python311\Lib\site-packages\starlette\routing.py", line 78, in app
    await wrap_app_handling_exceptions(app, request)(scope, receive, send)
  File "C:\Users\user1\AppData\Local\Programs\Python\Python311\Lib\site-packages\starlette\_exception_handler.py", line 53, in wrapped_app
    raise exc
  File "C:\Users\user1\AppData\Local\Programs\Python\Python311\Lib\site-packages\starlette\_exception_handler.py", line 42, in wrapped_app
    await app(scope, receive, sender)
  File "C:\Users\user1\AppData\Local\Programs\Python\Python311\Lib\site-packages\starlette\routing.py", line 75, in app
    response = await f(request)
               ^^^^^^^^^^^^^^^^
  File "C:\Users\user1\AppData\Local\Programs\Python\Python311\Lib\site-packages\fastapi\routing.py", line 308, in app
    raw_response = await run_endpoint_function(
                   ^^^^^^^^^^^^^^^^^^^^^^^^^^^^
  File "C:\Users\user1\AppData\Local\Programs\Python\Python311\Lib\site-packages\fastapi\routing.py", line 221, in run_endpoint_function
    return await run_in_threadpool(dependant.call, **values)
           ^^^^^^^^^^^^^^^^^^^^^^^^^^^^^^^^^^^^^^^^^^^^^^^^^
  File "C:\Users\user1\AppData\Local\Programs\Python\Python311\Lib\site-packages\starlette\concurrency.py", line 38, in run_in_threadpool
    return await anyio.to_thread.run_sync(func)
           ^^^^^^^^^^^^^^^^^^^^^^^^^^^^^^^^^^^^
  File "C:\Users\user1\AppData\Local\Programs\Python\Python311\Lib\site-packages\anyio\to_thread.py", line 33, in run_sync
    return await get_asynclib().run_sync_in_worker_thread(
           ^^^^^^^^^^^^^^^^^^^^^^^^^^^^^^^^^^^^^^^^^^^^^^^
  File "C:\Users\user1\AppData\Local\Programs\Python\Python311\Lib\site-packages\anyio\_backends\_asyncio.py", line 877, in run_sync_in_worker_thread
    return await future
           ^^^^^^^^^^^^
  File "C:\Users\user1\AppData\Local\Programs\Python\Python311\Lib\site-packages\anyio\_backends\_asyncio.py", line 807, in run
    result = context.run(func, *args)
             ^^^^^^^^^^^^^^^^^^^^^^^^
  File "C:\Users\user1\Desktop\fastapi\logtest.py", line 44, in error_demo
    raise ValueError("Simulated error for testing logs")
ValueError: Simulated error for testing logs

2025-10-09 10:52:23,019 | INFO | GET /visits | Status: 404 | Duration: 0.0s
2025-10-09 10:52:28,285 | INFO | GET /visits | Status: 404 | Duration: 0.001s
2025-10-09 10:55:13,189 | INFO | Visit count: 1
2025-10-09 10:55:13,199 | INFO | GET /visits | Status: 200 | Duration: 0.008s
2025-10-09 10:55:27,785 | INFO | Visit count: 2
2025-10-09 10:55:27,786 | INFO | GET / | Status: 404 | Duration: 0.0s
2025-10-09 10:55:37,335 | INFO | Visit count: 3
2025-10-09 10:55:37,339 | INFO | GET /visits | Status: 200 | Duration: 0.003s
2025-10-09 10:55:39,711 | INFO | Visit count: 4
2025-10-09 10:55:39,713 | INFO | GET /visits | Status: 200 | Duration: 0.002s
2025-10-09 10:55:40,630 | INFO | Visit count: 5
2025-10-09 10:55:40,631 | INFO | GET /visits | Status: 200 | Duration: 0.001s
2025-10-09 10:55:45,674 | INFO | Visit count: 6
2025-10-09 10:55:45,676 | INFO | GET /visits | Status: 200 | Duration: 0.0s
2025-10-09 10:55:47,168 | INFO | Visit count: 7
2025-10-09 10:55:47,169 | INFO | GET /visits | Status: 200 | Duration: 0.001s
2025-10-09 11:01:35,431 | INFO | Visit count: 8
2025-10-09 11:01:35,433 | INFO | GET /visits | Status: 200 | Duration: 0.002s
2025-10-09 11:03:08,354 | INFO | Visit count: 1
2025-10-09 11:03:08,356 | INFO | GET /visits | Status: 200 | Duration: 0.002s
2025-10-09 11:03:11,850 | INFO | Visit count: 2
2025-10-09 11:03:11,875 | INFO | GET /visits | Status: 200 | Duration: 0.025s
2025-10-09 11:03:12,965 | INFO | Visit count: 3
2025-10-09 11:03:12,966 | INFO | GET /visits | Status: 200 | Duration: 0.001s
2025-10-09 14:41:40,131 | INFO | GET / | Duration: 1.511s
2025-10-09 14:55:14,077 | INFO | Request: / took 2.0013 seconds
2025-10-09 14:55:44,665 | INFO | Request: / took 2.0012 seconds
2025-10-09 14:55:52,598 | INFO | Request: / took 2.0004 seconds
